Workbook

Sheet ПРАЙС_ЛИСТ
B2: МОДЕЛЬ | C2: КОД УСЛУГИ | D2: ГАРАНТИЯ, дн. | E2: УСЛУГА | F2: РОЗНИЧНАЯ ЦЕНА | G2: ДИАПОЗОН ЦЕНЫ
B3: iPhone | E3: Данные - резервная копия / перенос (1 - 128 ГБ) | *цена за фактический объем данных | F3: ='МАТРИЦА_СТОИМОСТИ_РАБОТ'!C5 -> 1600 | I3: 1000 - цена "от" | *требуется диагностика
E4: Данные - резервная копия / перенос (128 - 256 ГБ) | *цена за фактический объем данных | F4: ='МАТРИЦА_СТОИМОСТИ_РАБОТ'!C6 -> 2200 | I4: 1000 - фиксированная цена
E5: Данные - резервная копия / перенос (256 - 512 ГБ) | *цена за фактический объем данных | F5: ='МАТРИЦА_СТОИМОСТИ_РАБОТ'!C7 -> 4100 | I5: 1000 - цена "за работу" - уточнить запчасть .. стоимость .. наличие .. доступность заказа!
E6: Данные - резервная копия / перенос (512 ГБ - 1 ТБ) | *цена за фактический объем данных | F6: ='МАТРИЦА_СТОИМОСТИ_РАБОТ'!C8 -> 5100 | I6: есть дорогой закуп запчасти - предложить "вилку" из наличия / под заказ
E7: Данные - резервная копия / перенос (1 - 2 ТБ) | *цена за фактический объем данных | F7: ='МАТРИЦА_СТОИМОСТИ_РАБОТ'!C9 -> ?
E8: Приложения - установка | *цена за 1шт. | F8: ='МАТРИЦА_СТОИМОСТИ_РАБОТ'!C10 -> 500
E9: Прошивка / программные работы - БЕЗ РЕЗЕРВНОЙ копии | F9: ='МАТРИЦА_СТОИМОСТИ_РАБОТ'!C11 -> 1100
E10: Диагностика (без пайки компонентов) | F10: ='МАТРИЦА_СТОИМОСТИ_РАБОТ'!C17 -> 0
E11: Диагностика - составление и печать акта | F11: ='МАТРИЦА_СТОИМОСТИ_РАБОТ'!C18 -> 1000 | J11: МИН. ЦЕНА УСЛУГИ | K11: {={ "НАША ЦЕНА" ; IF(ROW(F12:F55), "", ); IF(F56:F1487="", "", F56:F1487) }} -> НАША ЦЕНА | L11: РЕМОНТ ЯБЛОК
B13: iPhone ШАБЛОН | D13: 0 | E13: Диагностика (с пайкой компонентов) | *бесплатно при дальнейшем ремонте | F13: -
B14: iPhone ШАБЛОН | D14: 0 | E14: Пылевлагозащита - восстановление | F14: -
B15: iPhone ШАБЛОН | D15: 0 | E15: Чистка сеток динамиков и разъема зарядки БЕЗ РАЗБОРА | F15: - | G15: =MIN(F15:F16) & " - " & MAX(F15:F16) -> 0 - 0
B16: iPhone ШАБЛОН | D16: 0 | E16: Чистка сеток динамиков и разъема зарядки С РАЗБОРОМ | F16: -
B17: iPhone ШАБЛОН | D17: 180 | E17: Аккумулятор - замена на СЕРВИСНЫЙ ОРИГИНАЛ (подлинное) | F17: - | G17: =MIN(F17:F22) & " - " & MAX(F17:F22) -> 0 - 0
B18: iPhone ШАБЛОН | D18: 180 | E18: Аккумулятор - замена на СНЯТЫЙ ОРИГИНАЛ (бу) | F18: -
B19: iPhone ШАБЛОН | D19: 180 | E19: Аккумулятор - замена на АНАЛОГ | F19: -
B20: iPhone ШАБЛОН | D20: 180 | E20: Аккумулятор - замена на АНАЛОГ (подлинное) | F20: -
B21: iPhone ШАБЛОН | D21: 180 | E21: Аккумулятор - замена на АНАЛОГ (бу) | F21: -
B22: iPhone ШАБЛОН | D22: 180 | E22: Аккумулятор - замена на АНАЛОГ (неизвестная деталь) | F22: -
B23: iPhone ШАБЛОН | D23: 180 | E23: Аккумулятор - замена с устранением уведомления | *цена под ключ | F23: -
B24: iPhone ШАБЛОН | D24: 90 | E24: Разъем зарядки - замена | F24: -
B25: iPhone ШАБЛОН | D25: 90 | E25: Дисплей - замена на СЕРВИСНЫЙ ОРИГИНАЛ (подлинное) | F25: - | G25: =MIN(F25:F34) & " - " & MAX(F25:F34) -> 0 - 0
B26: iPhone ШАБЛОН | D26: 90 | E26: Дисплей - замена на СНЯТЫЙ ОРИГИНАЛ | F26: -
B27: iPhone ШАБЛОН | D27: 90 | E27: Дисплей - замена на СНЯТЫЙ ОРИГИНАЛ (бу) | F27: -
B28: iPhone ШАБЛОН | D28: 90 | E28: Дисплей - замена на СНЯТЫЙ ОРИГИНАЛ (неизвестная деталь) | F28: -
B29: iPhone ШАБЛОН | D29: 90 | E29: Дисплей - замена на ВОССТАНОВЛЕННЫЙ ОРИГИНАЛ | F29: -
B30: iPhone ШАБЛОН | D30: 90 | E30: Дисплей - замена на ВОССТАНОВЛЕННЫЙ ОРИГИНАЛ (бу) | F30: -
B31: iPhone ШАБЛОН | D31: 90 | E31: Дисплей - замена на ВОССТАНОВЛЕННЫЙ ОРИГИНАЛ (неизвестная деталь) | F31: -
B32: iPhone ШАБЛОН | D32: 90 | E32: Дисплей - замена на АНАЛОГ | F32: -
B33: iPhone ШАБЛОН | D33: 90 | E33: Дисплей - замена на АНАЛОГ (бу) | F33: -
B34: iPhone ШАБЛОН | D34: 90 | E34: Дисплей - замена на АНАЛОГ (неизвестная деталь) | F34: -
B35: iPhone ШАБЛОН | D35: 90 | E35: Дисплей - устранение уведомления о замене | F35: -
B36: iPhone ШАБЛОН | D36: 90 | E36: Дисплей - замена (переклей) разбитого стекла | F36: - | G36: =MIN(F36:F37) & " - " & MAX(F36:F37) -> 0 - 0
B37: iPhone ШАБЛОН | D37: 90 | E37: Дисплей - замена (переклей) разбитого стекла с тачскрином | F37: -
B38: iPhone ШАБЛОН | D38: 90 | E38: Камера основная - замена | F38: -
B39: iPhone ШАБЛОН | D39: 90 | E39: Камера фронтальная - замена | F39: -
B40: iPhone ШАБЛОН | D40: 180 | E40: Камера - замена разбитого стекла | *цена за 1шт. | F40: -
B41: iPhone ШАБЛОН | D41: 90 | E41: Face ID - восстановление | *цена от, требуется диагностика | F41: -
B42: iPhone ШАБЛОН | D42: 180 | E42: Крышка (заднее стекло) - замена на СНЯТЫЙ ОРИГИНАЛ | F42: - | G42: =MIN(F42:F43) & " - " & MAX(F42:F43) -> 0 - 0
...

Sheet БД_МОЙ СКЛАД
B2: МОДЕЛЬ | C2: КОД | D2: ЦЕНА | E2: Услуга | F2: Время | G2: Цена "ОТ" | H2: Гарантия | I2: Ссылка | J2: Описание | L2: ЗАВИСИМОСТЬ
B3: iPhone 17 Pro Max | C3: 782129785272454612 | D3: =IF('ПРАЙС_ЛИСТ'!F1470 <> 'ПРАЙС_ЛИСТ'!H1470, IF('ПРАЙС_ЛИСТ'!F1470 = 1, 0, 'ПРАЙС_ЛИСТ'!F1470), 0) -> 38500 | E3: Замена стекла | F3: 30 мин | H3: 90 дней | I3: https://maxmobiles.ru/zamena-stekla-iphone-17-pro-max/ | J3: При поломке только стекла на Вашем аппарате, без ущерба для дисплея и сенсора, возможна замена только стекла. Мы выполняем эту процедуру с использованием профессионального оборудования, обеспечивая сохранение оригинального экрана
C4: 7821297852724555125 | D4: 0 | E4: Замена дисплея (копия) | F4: 30 мин | G4: уточняйте | H4: 90 дней | I4: https://maxmobiles.ru/zamena-displeya-iphone-17-pro-max-kopiya/ | J4: У нас есть несколько вариантов копий на любой кошелек! Разница заключается в цветопередаче и возможности использования функции True Tone
C5: 782129785272454591 | D5: {=MIN(IF('ПРАЙС_ЛИСТ'!F1462:F1466 <> 'ПРАЙС_ЛИСТ'!H1462:H1466, 'ПРАЙС_ЛИСТ'!F1462:F1466, ""))} -> 42050 | E5: Замена дисплея (оригинал) | F5: 30 мин | G5: цена от | H5: 90 дней | I5: https://maxmobiles.ru/zamena-displeya-iphone-17-pro-max/ | J5: Хотите, чтобы всё работало как по-старому? Тогда оригинальный дисплей — ваш выбор. Сохранится цветопередача, Face ID и True Tone | L5: типа запчасти
C6: 782129785272454630 | D6: {=MIN(IF('ПРАЙС_ЛИСТ'!F1475:F1476 <> 'ПРАЙС_ЛИСТ'!H1475:H1476, 'ПРАЙС_ЛИСТ'!F1475:F1476, ""))} -> 12000 | E6: Замена заднего стекла | F6: 120 мин | G6: цена от | H6: 180 дней | I6: https://maxmobiles.ru/zamena-zadney-kryshki-stekla-iphone-17-pro-max/ | J6: Повреждённая задняя панель не только ухудшает внешний вид смартфона, но и может стать источником микроскопических осколков. В Макмобайлс мы применяем лазерную технологию для замены стекла, что обеспечивает безопасность и сохранность аппарата | L6: типа запчасти
C7: 782129785272454633 | D7: ='ПРАЙС_ЛИСТ'!F1484 -> 10300 | E7: Чистка после попадания воды | F7: 30 мин | G7: цена от | H7: 90 дней | I7: https://maxmobiles.ru/profilaktika-posle-vody-iphone-17-pro-max/ | J7: Apple заявляет, что их гаджеты надёжно защищены от воды, но это не так. При этом не сохраняется официальная гарантия. Протрите, отключите телефон и бегом в сервис! | L7: повреждения
C8: 782129785272454566 | D8: {=MIN(IF('ПРАЙС_ЛИСТ'!F1455:F1460 <> 'ПРАЙС_ЛИСТ'!H1455:H1460, 'ПРАЙС_ЛИСТ'!F1455:F1460, ""))} -> 0 | E8: Замена аккумулятора | F8: 35 мин | G8: уточняйте | H8: 180 дней | I8: https://maxmobiles.ru/zamena-akkumulyatora-iphone-17-pro-max/ | J8: Аккумулятор нетрудно заменить, однако проблема может быть не в нём. Приходите на диагностику, и мы разберёмся, что нужно менять: АКБ, контроллер питания или разъём зарядки
C9: 782129785272454590 | D9: =IF('ПРАЙС_ЛИСТ'!F1461 <> 'ПРАЙС_ЛИСТ'!H1461, 'ПРАЙС_ЛИСТ'!F1461, "0") -> 19300 | E9: Замена разъема зарядки | F9: 35 мин | H9: 90 дней | I9: https://maxmobiles.ru/zamena-razema-zaryadki-iphone-17-pro-max/ | J9: Почему iPhone не заряжается? Это может быть как проблема с батареей, контроллером питания или разъёмом зарядки. Если причина неочевидна, определить её поможет диагностика
C10: 782129785272454629 | D10: =IF('ПРАЙС_ЛИСТ'!F1482 <> 'ПРАЙС_ЛИСТ'!H1482, 'ПРАЙС_ЛИСТ'!F1482, "0") -> 18100 | E10: Замена микрофона | F10: 30 мин | H10: 90 дней | I10: https://maxmobiles.ru/zamena-mikrofona-iphone-17-pro-max/ | J10: Эту поломку легко обнаружить при разговоре или записи, но устранить её сможет только квалифицированный мастер, ведь нужно разбирать устройство и менять шлейфы
C11: 782129785272454621 | D11: =IF('ПРАЙС_ЛИСТ'!F1480 <> 'ПРАЙС_ЛИСТ'!H1480, 'ПРАЙС_ЛИСТ'!F1480, "0") -> 0 | E11: Замена динамика | F11: 35 мин | G11: уточняйте | H11: 90 дней | I11: https://maxmobiles.ru/zamena-dinamika-gromkoy-svyazi-iphone-17-pro-max/ | J11: Динамик iPhone хрипит? Это могло произойти из-за воды, грязи или механического повреждения. Не рискуйте техникой — обращайтесь в наш сервис
C12: 782129785272454572 | D12: =IF('ПРАЙС_ЛИСТ'!F1481 <> 'ПРАЙС_ЛИСТ'!H1481, 'ПРАЙС_ЛИСТ'!F1481, "0") -> 0 | E12: Замена слухового динамика | F12: 35 мин | G12: уточняйте | H12: 90 дней | I12: https://maxmobiles.ru/zamena-dinamika-iphone-17-pro-max/ | J12: На замену верхнего динамика, как и нижнего, предоставляется гарантия 90 дней. Процедура нужна, если Вы не слышите собеседника, звук верхнего динамика отсутствует
C13: 782129785272454594 | D13: =IF('ПРАЙС_ЛИСТ'!F1471 <> 'ПРАЙС_ЛИСТ'!H1471, 'ПРАЙС_ЛИСТ'!F1471, "0") -> 17200 | E13: Замена камеры | F13: 40 мин | H13: 90 дней | I13: https://maxmobiles.ru/zamena-osnovnoy-kamery-iphone-17-pro-max/ | J13: Не работает камера iPhone? Приходите в сервис на диагностику. Выявим все неполадки и устраним в кратчайшие сроки
C14: 782129785272454597 | D14: =IF('ПРАЙС_ЛИСТ'!F1472 <> 'ПРАЙС_ЛИСТ'!H1472, 'ПРАЙС_ЛИСТ'!F1472, "0") -> 18500 | E14: Замена фронтальной камеры | F14: 35 мин | H14: 90 дней | I14: https://maxmobiles.ru/zamena-frontalnoy-kamery-iphone-17-pro-max/ | J14: Почему камера на Айфоне не работает? Проблема может быть в сбое ПО, механических повреждениях, замыкании
C15: 782129785272454615 | D15: =IF('ПРАЙС_ЛИСТ'!F1473 <> 'ПРАЙС_ЛИСТ'!H1473, 'ПРАЙС_ЛИСТ'!F1473, "0") -> 9600 | E15: Замена стекла камеры | F15: 35 мин | H15: 180 дней | I15: https://maxmobiles.ru/zamena-stekla-kamery-iphone-17-pro-max/ | J15: Повреждения камеры, проявляющиеся в виде отказа макросъемки и проблем с фокусировкой, обычно связаны с загрязнением подвижного объектива мелкими частицами. Если в камеру попала пыль или осколки стекла, это может нарушить её нормальную работу
C16: 782129785272454603 | D16: 0 | E16: Замена корпуса | F16: 60 мин | G16: уточняйте | H16: 180 дней | I16: https://maxmobiles.ru/zamena-korpusa-iphone-17-pro-max/ | J16: Для замены корпуса потребуется полная разборка аппарата. Не стоит поручать столь ответственную процедуру дилетантам. Сертифицированные инженеры Максмобайлс быстро и качественно выполнят все ремонтные работы и Ваш гаджет будет как новый
C17: 782129785272454628 | D17: 0 | E17: Ремонт кнопок | F17: 40 мин | G17: уточняйте | H17: 90 дней | I17: https://maxmobiles.ru/zamena-knopok-iphone-17-pro-max/ | J17: Регулировка громкости связана с другими элементами — кнопкой блокировки, переключателем вибро-режима, датчиком приближения и вспышкой. Эти детали объединяются верхним шлейфом, из-за чего при его повреждении может понадобиться комплексный ремонт
C18: 78212978527245362 | D18: =IF('ПРАЙС_ЛИСТ'!F9 <> 'ПРАЙС_ЛИСТ'!H9, 'ПРАЙС_ЛИСТ'!F9, "0") -> 1100 | E18: Прошивка | F18: 120 мин | I18: https://maxmobiles.ru/proshivka-bez-rezervnoy-kopii-iphone-11/ | J18: Только после оценки состояния Вашего девайса и выявления всех неполадок наш специалист сможет определить, нужна ли восстановительная прошивка или полная замена системного ПО
C19: 782129785272455011 | D19: ='ПРАЙС_ЛИСТ'!F1483 -> 8800 | E19: Ремонт материнской платы | F19: 180 мин | G19: цена от | H19: 90 дней | I19: https://maxmobiles.ru/remont-platy-iphone-17-pro-max/ | J19: Инженеры Максмобайлс проведут комплексную диагностику вашего iPhone, чтобы точно определить проблему. Мы используем современное оборудование для выявления неисправностей и восстановления работоспособности платы | L19: повреждения
C20: 782129785272454583 | D20: ='ПРАЙС_ЛИСТ'!F1474 -> 10800 | E20: Ремонт Face ID | F20: 180 мин | G20: цена от | H20: 90 дней | I20: https://maxmobiles.ru/remont-face-id-iphone-17-pro-max/ | J20: Если повредилась камера TrueDepth, распознавание лица не происходит либо вовсе невозможно, требуется замена Face ID | L20: повреждения
B22: iPhone 17 Pro | C22: 782129785272454577 | D22: =IF('ПРАЙС_ЛИСТ'!F1433 <> 'ПРАЙС_ЛИСТ'!H1433, IF('ПРАЙС_ЛИСТ'!F1433 = 1, 0, 'ПРАЙС_ЛИСТ'!F1433), 0) -> 0 | E22: Замена стекла | F22: 30 мин | G22: уточняйте | H22: 90 дней | I22: https://maxmobiles.ru/zamena-stekla-iphone-17-pro/ | J22: При поломке только стекла на Вашем аппарате, без ущерба для дисплея и сенсора, возможна замена только стекла. Мы выполняем эту процедуру с использованием профессионального оборудования, обеспечивая сохранение оригинального экрана
C23: 7821297852724555129 | D23: 0 | E23: Замена дисплея (копия) | F23: 30 мин | G23: уточняйте | H23: 90 дней | I23: https://maxmobiles.ru/zamena-displeya-iphone-17-pro-kopiya/ | J23: У нас есть несколько вариантов копий на любой кошелек! Разница заключается в цветопередаче и возможности использования функции True Tone
C24: 782129785272454639 | D24: {=MIN(IF('ПРАЙС_ЛИСТ'!F1425:F1429 <> 'ПРАЙС_ЛИСТ'!H1425:H1429, 'ПРАЙС_ЛИСТ'!F1425:F1429, ""))} -> 38650 | E24: Замена дисплея (оригинал) | F24: 30 мин | G24: цена от | H24: 90 дней | I24: https://maxmobiles.ru/zamena-displeya-iphone-17-pro/ | J24: Хотите, чтобы всё работало как по-старому? Тогда оригинальный дисплей — ваш выбор. Сохранится цветопередача, Face ID и True Tone | L24: типа запчасти
C25: 782129785272454635 | D25: {=MIN(IF('ПРАЙС_ЛИСТ'!F1438:F1439 <> 'ПРАЙС_ЛИСТ'!H1438:H1439, 'ПРАЙС_ЛИСТ'!F1438:F1439, ""))} -> 11000 | E25: Замена заднего стекла | F25: 120 мин | G25: цена от | H25: 180 дней | I25: https://maxmobiles.ru/zamena-zadney-kryshki-stekla-iphone-17-pro/ | J25: Повреждённая задняя панель не только ухудшает внешний вид смартфона, но и может стать источником микроскопических осколков. В Макмобайлс мы применяем лазерную технологию для замены стекла, что обеспечивает безопасность и сохранность аппарата | L25: типа запчасти
C26: 782129785272454647 | D26: ='ПРАЙС_ЛИСТ'!F1447 -> 10300 | E26: Чистка после попадания воды | F26: 30 мин | G26: цена от | H26: 90 дней | I26: https://maxmobiles.ru/profilaktika-posle-vody-iphone-17-pro/ | J26: Apple заявляет, что их гаджеты надёжно защищены от воды, но это не так. При этом не сохраняется официальная гарантия. Протрите, отключите телефон и бегом в сервис! | L26: повреждения
C27: 782129785272454579 | D27: {=MIN(IF('ПРАЙС_ЛИСТ'!F1418:F1423 <> 'ПРАЙС_ЛИСТ'!H1418:H1423, 'ПРАЙС_ЛИСТ'!F1418:F1423, ""))} -> 0 | E27: Замена аккумулятора | F27: 35 мин | G27: уточняйте | H27: 180 дней | I27: https://maxmobiles.ru/zamena-akkumulyatora-iphone-17-pro/ | J27: Аккумулятор нетрудно заменить, однако проблема может быть не в нём. Приходите на диагностику, и мы разберёмся, что нужно менять: АКБ, контроллер питания или разъём зарядки
C28: 782129785272454642 | D28: =IF('ПРАЙС_ЛИСТ'!F1424 <> 'ПРАЙС_ЛИСТ'!H1424, 'ПРАЙС_ЛИСТ'!F1424, "0") -> 18200 | E28: Замена разъема зарядки | F28: 35 мин | H28: 90 дней | I28: https://maxmobiles.ru/zamena-razema-zaryadki-iphone-17-pro/ | J28: Почему iPhone не заряжается? Это может быть как проблема с батареей, контроллером питания или разъёмом зарядки. Если причина неочевидна, определить её поможет диагностика
C29: 782129785272454645 | D29: =IF('ПРАЙС_ЛИСТ'!F1445 <> 'ПРАЙС_ЛИСТ'!H1445, 'ПРАЙС_ЛИСТ'!F1445, "0") -> 17000 | E29: Замена микрофона | F29: 30 мин | H29: 90 дней | I29: https://maxmobiles.ru/zamena-mikrofona-iphone-17-pro/ | J29: Эту поломку легко обнаружить при разговоре или записи, но устранить её сможет только квалифицированный мастер, ведь нужно разбирать устройство и менять шлейфы
C30: 782129785272454585 | D30: =IF('ПРАЙС_ЛИСТ'!F1443 <> 'ПРАЙС_ЛИСТ'!H1443, 'ПРАЙС_ЛИСТ'!F1443, "0") -> 0 | E30: Замена динамика | F30: 35 мин | G30: уточняйте | H30: 90 дней | I30: https://maxmobiles.ru/zamena-dinamika-gromkoy-svyazi-iphone-17-pro/ | J30: Динамик iPhone хрипит? Это могло произойти из-за воды, грязи или механического повреждения. Не рискуйте техникой — обращайтесь в наш сервис
C31: 782129785272454620 | D31: =IF('ПРАЙС_ЛИСТ'!F1444 <> 'ПРАЙС_ЛИСТ'!H1444, 'ПРАЙС_ЛИСТ'!F1444, "0") -> 0 | E31: Замена слухового динамика | F31: 35 мин | G31: уточняйте | H31: 90 дней | I31: https://maxmobiles.ru/zamena-dinamika-iphone-17-pro/ | J31: На замену верхнего динамика, как и нижнего, предоставляется гарантия 90 дней. Процедура нужна, если Вы не слышите собеседника, звук верхнего динамика отсутствует
C32: 782129785272454623 | D32: =IF('ПРАЙС_ЛИСТ'!F1434 <> 'ПРАЙС_ЛИСТ'!H1434, 'ПРАЙС_ЛИСТ'!F1434, "0") -> 16650 | E32: Замена камеры | F32: 40 мин | H32: 90 дней | I32: https://maxmobiles.ru/zamena-osnovnoy-kamery-iphone-17-pro/ | J32: Не работает камера iPhone? Приходите в сервис на диагностику. Выявим все неполадки и устраним в кратчайшие сроки
C33: 782129785272454626 | D33: =IF('ПРАЙС_ЛИСТ'!F1435 <> 'ПРАЙС_ЛИСТ'!H1435, 'ПРАЙС_ЛИСТ'!F1435, "0") -> 17300 | E33: Замена фронтальной камеры | F33: 35 мин | H33: 90 дней | I33: https://maxmobiles.ru/zamena-frontalnoy-kamery-iphone-17-pro/ | J33: Почему камера на Айфоне не работает? Проблема может быть в сбое ПО, механических повреждениях, замыкании
C34: 782129785272454605 | D34: =IF('ПРАЙС_ЛИСТ'!F1436 <> 'ПРАЙС_ЛИСТ'!H1436, 'ПРАЙС_ЛИСТ'!F1436, "0") -> 8900 | E34: Замена стекла камеры | F34: 35 мин | H34: 180 дней | I34: https://maxmobiles.ru/zamena-stekla-kamery-iphone-17-pro/ | J34: Повреждения камеры, проявляющиеся в виде отказа макросъемки и проблем с фокусировкой, обычно связаны с загрязнением подвижного объектива мелкими частицами. Если в камеру попала пыль или осколки стекла, это может нарушить её нормальную работу
C35: 782129785272454617 | D35: 0 | E35: Замена корпуса | F35: 60 мин | G35: уточняйте | H35: 180 дней | I35: https://maxmobiles.ru/zamena-korpusa-iphone-17-pro/ | J35: Для замены корпуса потребуется полная разборка аппарата. Не стоит поручать столь ответственную процедуру дилетантам. Сертифицированные инженеры Максмобайлс быстро и качественно выполнят все ремонтные работы и Ваш гаджет будет как новый
C36: 782129785272454614 | D36: 0 | E36: Ремонт кнопок | F36: 40 мин | G36: уточняйте | H36: 90 дней | I36: https://maxmobiles.ru/zamena-knopok-iphone-17-pro/ | J36: Регулировка громкости связана с другими элементами — кнопкой блокировки, переключателем вибро-режима, датчиком приближения и вспышкой. Эти детали объединяются верхним шлейфом, из-за чего при его повреждении может понадобиться комплексный ремонт
C37: 78212978527245362 | D37: =IF('ПРАЙС_ЛИСТ'!F9 <> 'ПРАЙС_ЛИСТ'!H9, 'ПРАЙС_ЛИСТ'!F9, "0") -> 1100 | E37: Прошивка | F37: 120 мин | I37: https://maxmobiles.ru/proshivka-bez-rezervnoy-kopii-iphone-11/ | J37: Только после оценки состояния Вашего девайса и выявления всех неполадок наш специалист сможет определить, нужна ли восстановительная прошивка или полная замена системного ПО
C38: 782129785272455010 | D38: ='ПРАЙС_ЛИСТ'!F1446 -> 8800 | E38: Ремонт материнской платы | F38: 180 мин | G38: цена от | H38: 90 дней | I38: https://maxmobiles.ru/remont-platy-iphone-17-pro/ | J38: Инженеры Максмобайлс проведут комплексную диагностику вашего iPhone, чтобы точно определить проблему. Мы используем современное оборудование для выявления неисправностей и восстановления работоспособности платы | L38: повреждения
C39: 782129785272454588 | D39: ='ПРАЙС_ЛИСТ'!F1437 -> 10800 | E39: Ремонт Face ID | F39: 180 мин | G39: цена от | H39: 90 дней | I39: https://maxmobiles.ru/remont-face-id-iphone-17-pro/ | J39: Если повредилась камера TrueDepth, распознавание лица не происходит либо вовсе невозможно, требуется замена Face ID | L39: повреждения
B41: iPhone 17 Air | C41: 782129785272454571 | D41: =IF('ПРАЙС_ЛИСТ'!F1396 <> 'ПРАЙС_ЛИСТ'!H1396, IF('ПРАЙС_ЛИСТ'!F1396 = 1, 0, 'ПРАЙС_ЛИСТ'!F1396), 0) -> 0 | E41: Замена стекла | F41: 30 мин | G41: уточняйте | H41: 90 дней | I41: https://maxmobiles.ru/zamena-stekla-iphone-air/ | J41: При поломке только стекла на Вашем аппарате, без ущерба для дисплея и сенсора, возможна замена только стекла. Мы выполняем эту процедуру с использованием профессионального оборудования, обеспечивая сохранение оригинального экрана
C42: 7821297852724555130 | D42: 0 | E42: Замена дисплея (копия) | F42: 30 мин | G42: уточняйте | H42: 90 дней | I42: https://maxmobiles.ru/zamena-displeya-iphone-air-kopiya/ | J42: У нас есть несколько вариантов копий на любой кошелек! Разница заключается в цветопередаче и возможности использования функции True Tone
C43: 782129785272454604 | D43: {=MIN(IF('ПРАЙС_ЛИСТ'!F1388:F1392 <> 'ПРАЙС_ЛИСТ'!H1388:H1392, 'ПРАЙС_ЛИСТ'!F1388:F1392, ""))} -> 39200 | E43: Замена дисплея (оригинал) | F43: 30 мин | G43: цена от | H43: 90 дней | I43: https://maxmobiles.ru/zamena-displeya-iphone-air/ | J43: Хотите, чтобы всё работало как по-старому? Тогда оригинальный дисплей — ваш выбор. Сохранится цветопередача, Face ID и True Tone | L43: типа запчасти
...

Sheet БД_УСЛУГИ_РО
B2: МОДЕЛЬ | C2: ШТРИХКОД | D2: ТИП | E2: НАИМЕНОВАНИЕ УСЛУГИ | F2: ОПИСАНИЕ | G2: ЕДИНИЦА ИЗМЕРЕНИЯ | H2: ГРУППА | I2: ГАРАНТИЯ | J2: ГАРАНТИЯ ПЕРИОД | K2: ДЛИТЕЛЬНОСТЬ | L2: СЕБЕСТОИМОСТЬ | M2: СУММА ВОЗНАГРАЖДЕНИЯ | N2: % ВОЗНАГРАЖДЕНИЯ | O2: УСЛОВИЕ ВОЗНАГРАЖДЕНИЯ | P2: СТОИМОСТЬ УСЛУГИ
B3: РЕМОНТ APPLE "ОБЩИЙ НАБОР УСЛУГ" | E3: Данные - резервная копия / перенос (1 - 128 ГБ) | *цена за фактический объем данных | I3: 0 | P3: 1600
E4: Данные - резервная копия / перенос (128 - 256 ГБ) | *цена за фактический объем данных | I4: 0 | P4: 2200
E5: Данные - резервная копия / перенос (256 - 512 ГБ) | *цена за фактический объем данных | I5: 0 | P5: 4100
E6: Данные - резервная копия / перенос (512 ГБ - 1 ТБ) | *цена за фактический объем данных | I6: 0 | P6: 5100
E7: Данные - резервная копия / перенос (1 - 2 ТБ) | *цена за фактический объем данных | I7: 0 | P7: ?
E8: Приложения - установка | *цена за 1шт. | I8: 0 | P8: 500
E9: Программное обеспечение - установка до 3х программ | I9: 0 | P9: 600
E10: Программное обеспечение - установка более 3х программ | I10: 0 | P10: 1100
E11: Mac OS - установка | I11: 0 | P11: 1600
E12: Windows OS - установка | I12: 0 | P12: 1600
E13: Microsoft Office - установка | I13: 0 | P13: 1600
E14: Прошивка / программные работы - БЕЗ РЕЗЕРВНОЙ копии | I14: 0 | P14: 1100
E15: Сопровождение - ремонт устройства ** | I15: 0 | P15: 1
E16: Сопровождение - обмен устройства ** | I16: 0 | P16: 1
E17: Схематическая работа ** | I17: 0 | P17: 1
E18: Компонентный ремонт ** | I18: 90 | P18: 1
E19: Модульный ремонт ** | I19: 90 | P19: 1
... E22: Диагностика - составление и печать акта | I22: 0 | P22: 1000
B24: iPhone ШАБЛОН | E24: [i___-DGN] iPhone ___ Диагностика (с пайкой компонентов) | *бесплатно при дальнейшем ремонте | I24: 0
E25: [i___-WTR1] iPhone ___ Пылевлагозащита (этап 1) - восстановление | I25: 0 | N25: 30 | O25: приб.
E26: [i___-WTR2] iPhone ___ Пылевлагозащита (этап 2) - восстановление | I26: 0 | N26: 30 | O26: приб.
E27: [i___-CLNB] iPhone ___ Чистка сеток динамиков и разъема зарядки БЕЗ РАЗБОРА | I27: 0
E28: [i___-CLN] iPhone ___ Чистка сеток динамиков и разъема зарядки С РАЗБОРОМ | I28: 0
E29: [i___-BAT] iPhone ___ Аккумулятор - замена | I29: 180
E30: [i___-BATE] iPhone ___ Аккумулятор - устранение уведомления о замене | I30: 180
E31: [i___-CHG] iPhone ___ Разъем зарядки - замена | I31: 90
E32: [i___-DIS] iPhone ___ Дисплей - замена | I32: 90
E33: [i___-DISE] iPhone ___ Дисплей - устранение уведомления о замене | I33: 90
E34: [i___-DGL] iPhone ___ Дисплей - замена (переклей) разбитого стекла | I34: 90 | N34: 20 | O34: приб.
E35: [i___-DGT] iPhone ___ Дисплей - замена (переклей) разбитого стекла с тачскрином | I35: 90 | N35: 20 | O35: приб.
E36: [i___-CAMR] iPhone ___ Камера основная - замена | I36: 90
E37: [i___-CAMF] iPhone ___ Камера фронтальная - замена | I37: 90
E38: [i___-CGL] iPhone ___ Камера - замена разбитого стекла | *цена за 1шт. | I38: 180 | N38: 50 | O38: приб.
E39: [i___-FID] iPhone ___ Face ID - восстановление | *требуется диагностика | I39: 90
E40: [i___-BGL] iPhone ___ Крышка (заднее стекло) - замена | I40: 180
E41: [i___-HSG] iPhone ___ Корпус - замена | I41: 180
E42: [i___-MID] iPhone ___ Корпус (средняя часть) - замена | I42: 180
E43: [i___-HOM] iPhone ___ Кнопка Home - восстановление / замена | I43: 90
E44: [i___-BTN] iPhone ___ Кнопки - восстановление / замена | *требуется диагностика | I44: 90
...

Sheet БД_УСЛУГИ_МС
B2: МОДЕЛЬ | C2: ГАРАНТИЯ, дн. | D2: КОД УСЛУГИ | E2: УСЛУГА | F2: ЦЕНА
B3: iPhone | C3: 0 | D3: 78212978527245361 | E3: Данные - резервная копия / перенос (1 - 128 ГБ) | *цена за фактический объем данных | F3: ='ПРАЙС_ЛИСТ'!F3 -> 1600 | H3: 1000 - цена "от" | *требуется диагностика
C4: 0 | E4: Данные - резервная копия / перенос (129 - 256 ГБ) | *цена за фактический объем данных | F4: ='ПРАЙС_ЛИСТ'!F4 -> 2200 | H4: 1000 - фиксированная цена
C5: 0 | E5: Данные - резервная копия / перенос (257 - 512 ГБ) | *цена за фактический объем данных | F5: ='ПРАЙС_ЛИСТ'!F5 -> 4100 | H5: 1000 - цена "за работу" - уточнить стоимость и наличие запчасти у поставщиков!
C6: 0 | E6: Данные - резервная копия / перенос (513 - 1024 ГБ) | *цена за фактический объем данных | F6: ='ПРАЙС_ЛИСТ'!F6 -> 5100 | H6: есть дорогой закуп запчасти - предложить "вилку" из наличия / под заказ
C7: 0 | E7: Данные - резервная копия / перенос (1025 - 2056 ГБ) | *цена за фактический объем данных | F7: ='ПРАЙС_ЛИСТ'!F7 -> ?
C8: 0 | D8: 78212978527245363 | E8: Приложения - установка | *цена за 1шт. / 2-5 = скидка 25% / более 5 = скидка 30% | F8: ='ПРАЙС_ЛИСТ'!F8 -> 500
C9: 0 | D9: 78212978527245362 | E9: Прошивка iPhone - БЕЗ РЕЗЕРВНОЙ копии | F9: ='ПРАЙС_ЛИСТ'!F9 -> 1100
C10: 0 | E10: Диагностика (без пайки компонентов) | F10: ='ПРАЙС_ЛИСТ'!F10 -> 0
C11: 0 | E11: Диагностика - составление и печать акта | F11: ='ПРАЙС_ЛИСТ'!F11 -> 1000
B13: iPhone ШАБЛОН | C13: 0 | E13: iPhone ШАБЛОН Диагностика (с пайкой компонентов) | *бесплатно при дальнейшем ремонте | F13: -
B14: iPhone ШАБЛОН | C14: 0 | E14: iPhone ШАБЛОН Чистка сеток динамиков и разъема зарядки БЕЗ РАЗБОРА (минимальная) | F14: -
B15: iPhone ШАБЛОН | C15: 0 | E15: iPhone ШАБЛОН Чистка сеток динамиков и разъема зарядки С РАЗБОРОМ (максимальная) | F15: -
B16: iPhone ШАБЛОН | C16: 180 | E16: iPhone ШАБЛОН Аккумулятор - замена (минимальная) | F16: -
B17: iPhone ШАБЛОН | C17: 180 | E17: iPhone ШАБЛОН Аккумулятор - замена (максимальная) | F17: -
B18: iPhone ШАБЛОН | C18: 90 | E18: iPhone ШАБЛОН Разъем зарядки - замена | F18: -
B19: iPhone ШАБЛОН | C19: 90 | E19: iPhone ШАБЛОН Дисплей - замена (минимальная) | F19: -
B20: iPhone ШАБЛОН | C20: 90 | E20: iPhone ШАБЛОН Дисплей - замена (максимальная) | F20: -
B21: iPhone ШАБЛОН | C21: 90 | E21: iPhone ШАБЛОН Дисплей - замена разбитого стекла (минимальная) | F21: -
B22: iPhone ШАБЛОН | C22: 90 | E22: iPhone ШАБЛОН Дисплей - замена разбитого стекла с тачскрином (максимальная) | F22: -
B23: iPhone ШАБЛОН | C23: 90 | E23: iPhone ШАБЛОН Камера основная - замена | F23: -
B24: iPhone ШАБЛОН | C24: 90 | E24: iPhone ШАБЛОН Камера фронтальная - замена | F24: -
... B39: iPhone ШАБЛОН | C39: 90 | E39: iPhone ШАБЛОН WiFi / Bluetooth - восстановление беспроводных сетей | *цена от, требуется диагностика | F39: -
B41: iPhone 5 | C41: 0 | E41: iPhone 5 Диагностика (с пайкой компонентов) | *бесплатно при дальнейшем ремонте | F41: 0
B42: iPhone 5 | C42: 0 | D42: 67567465236906 | E42: iPhone 5 Чистка сеток динамиков и разъема зарядки БЕЗ РАЗБОРА (минимальная) | F42: ='ПРАЙС_ЛИСТ'!F57 -> 400
B43: iPhone 5 | C43: 0 | E43: iPhone 5 Чистка сеток динамиков и разъема зарядки С РАЗБОРОМ (максимальная) | F43: ='ПРАЙС_ЛИСТ'!F58 -> 900
B44: iPhone 5 | C44: 180 | D44: 67567465236905 | E44: iPhone 5 Аккумулятор - замена | F44: ='ПРАЙС_ЛИСТ'!F59 -> 1200
B45: iPhone 5 | C45: 90 | D45: 67567465236921 | E45: iPhone 5 Разъем зарядки - замена | F45: ='ПРАЙС_ЛИСТ'!F60 -> 750
B46: iPhone 5 | C46: 90 | D46: 67567465236911 | E46: iPhone 5 Дисплей - замена | F46: ='ПРАЙС_ЛИСТ'!F63 -> 800 | H46: только аналог
B47: iPhone 5 | C47: 90 | D47: 67567465236916 | E47: iPhone 5 Камера основная - замена | F47: ='ПРАЙС_ЛИСТ'!F64 -> 750
B48: iPhone 5 | C48: 90 | D48: 67567465236917 | E48: iPhone 5 Камера фронтальная - замена | F48: ='ПРАЙС_ЛИСТ'!F65 -> 750
B49: iPhone 5 | C49: 90 | D49: 67567465236915 | E49: iPhone 5 Камера - замена разбитого стекла | *цена за 1шт. | F49: =IF('ПРАЙС_ЛИСТ'!F66 = G49, 0, 'ПРАЙС_ЛИСТ'!F66) -> 0 | G49: ='БД_УСЛУГИ_РО'!P64 -> 500
B50: iPhone 5 | C50: 180 | D50: 67567465236918 | E50: iPhone 5 Корпус - замена | F50: =IF('ПРАЙС_ЛИСТ'!F67 = G50, 0, 'ПРАЙС_ЛИСТ'!F67) -> 0 | G50: ='БД_УСЛУГИ_РО'!P65 -> 800
B51: iPhone 5 | C51: 90 | D51: 67567465236922 | E51: iPhone 5 Кнопка HOME - восстановление / замена | F51: =IF('ПРАЙС_ЛИСТ'!F68 = G51, 0, 'ПРАЙС_ЛИСТ'!F68) -> 0 | G51: ='БД_УСЛУГИ_РО'!P66 -> 700
B52: iPhone 5 | C52: 90 | D52: 67567465236929 | E52: iPhone 5 Кнопки - восстановление / замена | *цена от, требуется диагностика | F52: ='ПРАЙС_ЛИСТ'!F69 -> 700
B53: iPhone 5 | C53: 90 | D53: 67567465236908 | E53: iPhone 5 Динамик полифонический - замена | F53: ='ПРАЙС_ЛИСТ'!F70 -> 850
B54: iPhone 5 | C54: 90 | D54: 67567465236909 | E54: iPhone 5 Динамик слуховой - замена | F54: ='ПРАЙС_ЛИСТ'!F71 -> 850
B55: iPhone 5 | C55: 90 | D55: 67567465236910 | E55: iPhone 5 Микрофон - замена (один из..) | *требуется диагностика | F55: ='ПРАЙС_ЛИСТ'!F72 -> 1050
B56: iPhone 5 | C56: 90 | D56: 782129785272455013 | E56: iPhone 5 Ремонт платы - восстановление / замена | *цена от, требуется диагностика | F56: ='ПРАЙС_ЛИСТ'!F73 -> 1600
B57: iPhone 5 | C57: 90 | D57: 67567465236920 | E57: iPhone 5 Профилактика после воды - восстановление | *цена от, требуется диагностика | F57: ='ПРАЙС_ЛИСТ'!F74 -> 2000
...

Sheet МАТРИЦА_СТОИМОСТИ_РАБОТ
B2: КОЭФИЦИЕНТ МОДЕЛИ | D2: 0.27 | E2: 0.33 | F2: 0.45 | G2: 0.5 | H2: 0.6 | I2: 0.76 | J2: 0.76 | K2: 0.87 | L2: 0.87 | M2: 1 | N2: 1 | O2: 1.15 | P2: 1.15 | Q2: 1.32 | R2: 1.32 | S2: 1.52 | T2: 1.52 | U2: 1.75 | V2: 1.75
B3: НАДБАВКА ДЛЯ PRO СЕРИИ | D3: 1 | E3: 1 | F3: 1 | G3: 1 | H3: 1 | I3: 1 | J3: 1.05 | K3: 1 | L3: 1.05 | M3: 1 | N3: 1.05 | O3: 1 | P3: 1.05 | Q3: 1 | R3: 1.05 | S3: 1 | T3: 1.05 | U3: 1 | V3: 1.05
B4: НАИМЕНОВАНИЕ | МОДЕЛЬ | C4: НЕ ЗАВИСИТ ОТ МОДЕЛИ | D4: {={ "5 SE 2016"; MAKEARRAY(15, 1, LAMBDA(r,c, "")); IF(M20:M48="", "", MROUND(M20:M48 * D2 * D3, 50)) }} -> 5 SE 2016 | E4: {={ "6"; MAKEARRAY(15, 1, LAMBDA(r,c, "")); IF(M20:M48="", "", MROUND(M20:M48 * E2 * E3, 50)) }} -> 6 | F4: {={ "7"; MAKEARRAY(15, 1, LAMBDA(r,c, "")); IF(M20:M48="", "", MROUND(M20:M48 * F2 * F3, 50)) }} -> 7 | G4: {={ "8 SE 2020 SE 2022"; MAKEARRAY(15, 1, LAMBDA(r,c, "")); IF(M20:M48="", "", MROUND(M20:M48 * G2 * G3, 50)) }} -> 8 SE 2020 SE 2022 | H4: {={ "X"; MAKEARRAY(15, 1, LAMBDA(r,c, "")); IF(M20:M48="", "", MROUND(M20:M48 * H2 * H3, 50)) }} -> X | I4: {={ "11"; MAKEARRAY(15, 1, LAMBDA(r,c, "")); IF(M20:M48="", "", MROUND(M20:M48 * I2 * I3, 50)) }} -> 11 | J4: {={ "11 Pro 11 Pro Max"; MAKEARRAY(15, 1, LAMBDA(r,c, "")); IF(M20:M48="", "", MROUND(M20:M48 * J2 * J3, 50)) }} -> 11 Pro 11 Pro Max | K4: {={ "12 12 Mini"; MAKEARRAY(15, 1, LAMBDA(r,c, "")); IF(M20:M48="", "", MROUND(M20:M48 * K2 * K3, 50)) }} -> 12 12 Mini | L4: {={ "12 Pro 12 Pro Max"; MAKEARRAY(15, 1, LAMBDA(r,c, "")); IF(M20:M48="", "", MROUND(M20:M48 * L2 * L3, 50)) }} -> 12 Pro 12 Pro Max | M4: 13 13 Mini | N4: {={ "13 Pro 13 Pro Max"; MAKEARRAY(15, 1, LAMBDA(r,c, "")); IF(M20:M48="", "", MROUND(M20:M48 * N2 * N3, 50)) }} -> 13 Pro 13 Pro Max | O4: {={ "14 14 Plus"; MAKEARRAY(15, 1, LAMBDA(r,c, "")); IF(M20:M48="", "", MROUND(M20:M48 * O2 * O3, 50)) }} -> 14 14 Plus | P4: {={ "14 Pro 14 Pro Max"; MAKEARRAY(15, 1, LAMBDA(r,c, "")); IF(M20:M48="", "", MROUND(M20:M48 * P2 * P3, 50)) }} -> 14 Pro 14 Pro Max | Q4: {={ "15 15 Plus"; MAKEARRAY(15, 1, LAMBDA(r,c, "")); IF(M20:M48="", "", MROUND(M20:M48 * Q2 * Q3, 50)) }} -> 15 15 Plus | R4: {={ "15 Pro 15 Pro Max"; MAKEARRAY(15, 1, LAMBDA(r,c, "")); IF(M20:M48="", "", MROUND(M20:M48 * R2 * R3, 50)) }} -> 15 Pro 15 Pro Max | S4: {={ "16 16E 16 Plus"; MAKEARRAY(15, 1, LAMBDA(r,c, "")); IF(M20:M48="", "", MROUND(M20:M48 * S2 * S3, 50)) }} -> 16 16E 16 Plus | T4: {={ "16 Pro 16 Pro Max"; MAKEARRAY(15, 1, LAMBDA(r,c, "")); IF(M20:M48="", "", MROUND(M20:M48 * T2 * T3, 50)) }} -> 16 Pro 16 Pro Max | U4: {={ "17 17 Air"; MAKEARRAY(15, 1, LAMBDA(r,c, "")); IF(M20:M48="", "", MROUND(M20:M48 * U2 * U3, 50)) }} -> 17 17 Air | V4: {={ "17 Pro 17 Pro Max"; MAKEARRAY(15, 1, LAMBDA(r,c, "")); IF(M20:M48="", "", MROUND(M20:M48 * V2 * V3, 50)) }} -> 17 Pro 17 Pro Max
B5: Данные - резервная копия / перенос (1 - 128 ГБ) | *цена за фактический объем данных | C5: 1600
B6: Данные - резервная копия / перенос (128 - 256 ГБ) | *цена за фактический объем данных | C6: 2200
B7: Данные - резервная копия / перенос (256 - 512 ГБ) | *цена за фактический объем данных | C7: 4100
B8: Данные - резервная копия / перенос (512 ГБ - 1 ТБ) | *цена за фактический объем данных | C8: 5100
B9: Данные - резервная копия / перенос (1 - 2 ТБ) | *цена за фактический объем данных | C9: ?
B10: Приложения - установка | *цена за 1шт. | C10: 500
B11: Прошивка - БЕЗ РЕЗЕРВНОЙ копии | C11: 1100
B12: Сопровождение - ремонт устройства * | C12: 1
B13: Сопровождение - обмен устройства * | C13: 1
B14: Схематическая работа * | C14: 1
B15: Компонентный ремонт * | C15: 1
B16: Модульный ремонт * | C16: 1
B17: Диагностика (без пайки компонентов) | C17: 0
B18: Диагностика - составление и печать акта | C18: 1000
B20: Диагностика (с пайкой компонентов) | *бесплатно при дальнейшем ремонте | D20: 250 | E20: 300 | F20: 400 | G20: 450 | H20: 550 | I20: 700 | J20: 700 | K20: 800 | L20: 800 | M20: 900 | N20: 950 | O20: 1050 | P20: 1100 | Q20: 1200 | R20: 1250 | S20: 1350 | T20: 1450 | U20: 1600 | V20: 1650
B21: Влагозащита (этап 1) - восстановление | D21: 200 | E21: 250 | F21: 300 | G21: 350 | H21: 400 | I21: 550 | J21: 550 | K21: 600 | L21: 650 | M21: 700 | N21: 750 | O21: 800 | P21: 850 | Q21: 900 | R21: 950 | S21: 1050 | T21: 1100 | U21: 1250 | V21: 1300
B22: Влагозащита (этап 2) - восстановление | D22: 200 | E22: 250 | F22: 300 | G22: 350 | H22: 400 | I22: 550 | J22: 550 | K22: 600 | L22: 650 | M22: 700 | N22: 750 | O22: 800 | P22: 850 | Q22: 900 | R22: 950 | S22: 1050 | T22: 1100 | U22: 1250 | V22: 1300
B23: Чистка сеток динамиков и разъема зарядки БЕЗ РАЗБОРА | D23: 150 | E23: 150 | F23: 250 | G23: 250 | H23: 300 | I23: 400 | J23: 400 | K23: 450 | L23: 450 | M23: 500 | N23: 550 | O23: 600 | P23: 600 | Q23: 650 | R23: 700 | S23: 750 | T23: 800 | U23: 900 | V23: 900
B24: Чистка сеток динамиков и разъема зарядки С РАЗБОРОМ | D24: 1000 | E24: 1200 | F24: 1650 | G24: 1850 | H24: 2200 | I24: 2800 | J24: 2950 | K24: 3200 | L24: 3400 | M24: 3700 | N24: 3900 | O24: 4250 | P24: 4450 | Q24: 4900 | R24: 5150 | S24: 5600 | T24: 5900 | U24: 6500 | V24: 6800
B25: Аккумулятор - замена | D25: 1100 | E25: 1300 | F25: 1800 | G25: 2000 | H25: 2400 | I25: 3050 | J25: 3200 | K25: 3500 | L25: 3650 | M25: 4000 | N25: 4200 | O25: 4600 | P25: 4850 | Q25: 5300 | R25: 5550 | S25: 6100 | T25: 6400 | U25: 7000 | V25: 7350
B26: Аккумулятор - устранение уведомления о замене | D26: 850 | E26: 1050 | F26: 1450 | G26: 1600 | H26: 1900 | I26: 2450 | J26: 2550 | K26: 2800 | L26: 2900 | M26: 3200 | N26: 3350 | O26: 3700 | P26: 3850 | Q26: 4200 | R26: 4450 | S26: 4850 | T26: 5100 | U26: 5600 | V26: 5900
B27: Разъем зарядки - замена | D27: 1100 | E27: 1300 | F27: 1800 | G27: 2000 | H27: 2400 | I27: 3050 | J27: 3200 | K27: 3500 | L27: 3650 | M27: 4000 | N27: 4200 | O27: 4600 | P27: 4850 | Q27: 5300 | R27: 5550 | S27: 6100 | T27: 6400 | U27: 7000 | V27: 7350
B28: Дисплей - замена | D28: 1100 | E28: 1300 | F28: 1800 | G28: 2000 | H28: 2400 | I28: 3050 | J28: 3200 | K28: 3500 | L28: 3650 | M28: 4000 | N28: 4200 | O28: 4600 | P28: 4850 | Q28: 5300 | R28: 5550 | S28: 6100 | T28: 6400 | U28: 7000 | V28: 7350
B29: Дисплей - устранение уведомления о замене | D29: 900 | E29: 1100 | F29: 1500 | G29: 1650 | H29: 2000 | I29: 2500 | J29: 2650 | K29: 2850 | L29: 3000 | M29: 3300 | N29: 3450 | O29: 3800 | P29: 4000 | Q29: 4350 | R29: 4550 | S29: 5000 | T29: 5250 | U29: 5800 | V29: 6050
B30: Дисплей - замена разбитого стекла | D30: 1100 | E30: 1300 | F30: 1800 | G30: 2000 | H30: 2400 | I30: 3050 | J30: 3200 | K30: 3500 | L30: 3650 | M30: 4000 | N30: 4200 | O30: 4600 | P30: 4850 | Q30: 5300 | R30: 5550 | S30: 6100 | T30: 6400 | U30: 7000 | V30: 7350
B31: Дисплей - замена разбитого стекла с тачскрином | D31: 1100 | E31: 1300 | F31: 1800 | G31: 2000 | H31: 2400 | I31: 3050 | J31: 3200 | K31: 3500 | L31: 3650 | M31: 4000 | N31: 4200 | O31: 4600 | P31: 4850 | Q31: 5300 | R31: 5550 | S31: 6100 | T31: 6400 | U31: 7000 | V31: 7350
... B47: WiFi / Bluetooth - восстановление беспроводных сетей | *требуется диагностика | D47: 1400 | E47: 1700 | F47: 2350 | G47: 2600 | H47: 3100 | I47: 3950 | J47: 4150 | K47: 4500 | L47: 4750 | M47: 5200 | N47: 5450 | O47: 6000 | P47: 6300 | Q47: 6850 | R47: 7200 | S47: 7900 | T47: 8300 | U47: 9100 | V47: 9550

Sheet РЕМОНТ_ЯБЛОК
G4: Обновлено: 05.05.2026 11:44
B5: iPhone 5 | C5: iPhone 5 Диагностика | D5: 0 | E5: 1 мес.
C6: iPhone 5 Защитное стекло | D6: 200 | E6: 1 мес.
C7: iPhone 5 Переклейка (восстановление) вашего дисплея | D7: 1500 | E7: 1 мес.
C8: iPhone 5 Замена дисплея (оригинал) | D8: 3000 | E8: 1 мес.
C9: iPhone 5 Замена дисплея (аналог) | D9: 2000 | E9: 1 мес.
C10: iPhone 5 Замена динамика | D10: 800 | E10: 1 мес.
C11: iPhone 5 Замена микрофона | D11: 1200 | E11: 1 мес.
C12: iPhone 5 Ремонт кнопки включения | D12: 1200 | E12: 1 мес.
C13: iPhone 5 Ремонт кнопок громкости | D13: 1200 | E13: 1 мес.
C14: iPhone 5 Замена аккумулятора (1440mAh) 3.8V Standard | D14: 1200 | E14: 1 мес.
C15: iPhone 5 Замена аккумулятора (1800mAh) 3.8V HC (повышенная емкость) | D15: 1600 | E15: 1 мес.
C16: iPhone 5 Замена основной камеры | D16: 1200 | E16: 1 мес.
C17: iPhone 5 Замена фронтальной камеры | D17: 1000 | E17: 1 мес.
... C25: iPhone 5 Разблокировка | D25: 900 | E25: 1 мес.
B27: iPhone 5C | C27: iPhone 5C Диагностика | D27: 0 | E27: 1 мес.
C28: iPhone 5C Защитное стекло | D28: 200 | E28: 1 мес.
C29: iPhone 5C Переклейка (восстановление) вашего дисплея | D29: 1500 | E29: 1 мес.
C30: iPhone 5C Замена дисплея (оригинал) | D30: 3000 | E30: 1 мес.
C31: iPhone 5C Замена дисплея (аналог) | D31: 2000 | E31: 1 мес.
C32: iPhone 5C Замена динамика | D32: 800 | E32: 1 мес.
C33: iPhone 5C Замена микрофона | D33: 1200 | E33: 1 мес.
C34: iPhone 5C Ремонт кнопки включения | D34: 1200 | E34: 1 мес.
C35: iPhone 5C Ремонт кнопок громкости | D35: 1200 | E35: 1 мес.
C36: iPhone 5C Замена аккумулятора (1560mAh) 3.8V Standard | D36: 1200 | E36: 1 мес.
C37: iPhone 5C Замена аккумулятора (1800mAh) 3.8V HC (повышенная емкость) | D37: 1600 | E37: 1 мес.
C38: iPhone 5C Замена основной камеры | D38: 1200 | E38: 1 мес.
C39: iPhone 5C Замена фронтальной камеры | D39: 1000 | E39: 1 мес.
... C47: iPhone 5C Разблокировка | D47: 900 | E47: 1 мес.
B49: iPhone 5S | C49: iPhone 5S Диагностика | D49: 0 | E49: 1 мес.
C50: iPhone 5S Защитное стекло | D50: 200 | E50: 1 мес.
C51: iPhone 5S Переклейка (восстановление) вашего дисплея | D51: 1500 | E51: 1 мес.
C52: iPhone 5S Замена дисплея (оригинал) | D52: 2500 | E52: 1 мес.
C53: iPhone 5S Замена дисплея (аналог) | D53: 2000 | E53: 1 мес.
C54: iPhone 5S Замена динамика | D54: 800 | E54: 1 мес.
C55: iPhone 5S Замена микрофона | D55: 1200 | E55: 1 мес.
C56: iPhone 5S Ремонт кнопки включения | D56: 1200 | E56: 1 мес.
C57: iPhone 5S Ремонт кнопок громкости | D57: 1200 | E57: 1 мес.
C58: iPhone 5S Замена аккумулятора (1560mAh) 3.8V Standard | D58: 1200 | E58: 1 мес.
C59: iPhone 5S Замена аккумулятора (1800mAh) 3.8V HC (повышенная емкость) | D59: 1600 | E59: 1 мес.
...

Sheet БД_ЗАПЧАСТИ
G2: ПАРСИНГ
G3: ICOMPONENTS | J3: MOS - LCD | U3: НАЦЕНКА В РУБЛЯХ | X3: ЦЕНЫ НА ЗАПЧАСТИ
B4: НАИМЕНОВАНИЕ ЗАПЧАСТИ | C4: ID ЗАПЧАСТИ | D4: ГАРАНТИЯ | E4: МОДЕЛЬ | F4: КАТЕГОРИЯ | G4: НАИМЕНОВАНИЕ НА САЙТЕ ICOMPONENTS | H4: СТАРАЯ ЦЕНА ЗАПЧАСТИ ICOMPONENTS | I4: АКТ. ЦЕНА ЗАПЧАСТИ ICOMPONENTS | J4: НАИМЕНОВАНИЕ В ПРАЙСЕ MOS - LCD | K4: СТАРАЯ ЦЕНА ЗАПЧАСТИ MOS - LCD | L4: АКТ. ЦЕНА ЗАПЧАСТИ MOS - LCD | M4: {={"ПОДХОДЯЩАЯ ЦЕНА ЗАПЧАСТИ*"; BYROW(H5:L921, LAMBDA(row, IF(COUNT(row)>0, MAX(row), "")))}} -> ПОДХОДЯЩАЯ ЦЕНА ЗАПЧАСТИ* | N4: НАЦЕНКА НА ЗАПЧАСТЬ | O4: {={"СТОИМОСТЬ ЗАПЧАСТИ С НАЦЕНКОЙ*"; IF(M5:M921<>"", MROUND(M5:M921*(1+N5:N921), 50), "")}} -> СТОИМОСТЬ ЗАПЧАСТИ С НАЦЕНКОЙ* | P4: ИТОГОВАЯ СТОИМОСТЬ ЗАПЧАСТИ (ПРАЙС) | Q4: ИТОГОВАЯ СТОИМОСТЬ ЗАПЧАСТИ (РЕМОНЛАЙН) | R4: ССЫЛКА НА ЗАПЧАСТЬ ICOMPONENTS | S4: ДАТА ПАРСИНГА | U4: НАЦЕНКА В РУБЛЯХ ICOMPONENTS | V4: НАЦЕНКА В РУБЛЯХ MOS - LCD | X4: {={"ЦЕНА ICOMPONENTS*"; I5:I921}} -> ЦЕНА ICOMPONENTS* | Y4: {={"ЦЕНА MOS - LCD*"; L5:L921}} -> ЦЕНА MOS - LCD* | AA4: {={"ID*"; C5:C921}} -> ID* | AB4: {={"КОД*"; AA5:AA921}} -> КОД* | AC4: Артикул | AD4: {={"ШТРИХКОД*"; AA5:AA921}} -> ШТРИХКОД* | AE4: {={"Наименование*"; B5:B921}} -> Наименование* | AF4: Описание | AG4: {={ "Единица измерения*" ; IF(AG5:AG921 <> "", "pcs", "pcs") }} -> Единица измерения* | AH4: Категория | AI4: {={"Гарантия*"; D5:D921}} -> Гарантия* | AJ4: {={ "Гарантийный период*" ; IF(AJ5:AJ921 <> "", "дн", "дн") }} -> Гарантийный период* | AK4: Серийный учет | AL4: {={ "Включить отслеживание срока годности*" ; IF(AL5:AL921 <> "", "нет", "нет") }} -> Включить отслеживание срока годности* | AM4: Длина | AN4: Ширина | AO4: Высота | AP4: Единица измерения размеров | AQ4: Вес | AR4: Единица веса | AS4: ID поставщика по умолчанию | AT4: Имя поставщика по умолчанию | AU4: {={"Закупочная*"; M5:M921}} -> Закупочная* | AV4: {={"Розничная*"; Q5:Q921}} -> Розничная*
B5: iPhone 5 [BAT] Аккумулятор - Аналог ORIG | C5: 161 990 | D5: 180 | E5: =LEFT(B5,FIND("[",B5) - 2) -> iPhone 5 | F5: Аккумулятор | G5: iPhone 5 - аккумуляторная батарея (АКБ), ORIG | I5: 430 | L5: 340 | M5: 430 | N5: 0.12 | O5: 500 | P5: =O5 -> 500 | Q5: =P5 -> 500 | R5: https://icomponents.ru/catalog/iphone/iphone_5/iphone_5_akkumulyatornaya_batareya_akb_orig/ | S5: 46140.38 | U5: =IF(I5>0, Q5 - I5, "нет з/ч") -> 70 | V5: =IF(L5>0, Q5 - L5, "нет з/ч") -> 160 | X5: 430 | Y5: 340 | AA5: 161 990 | AB5: 161 990 | AD5: 161 990 | AE5: iPhone 5 [BAT] Аккумулятор - Аналог ORIG | AG5: pcs | AH5: Сервис > Ремонт Apple > Ремонт iPhone > 5 | AI5: 180 | AJ5: дн | AK5: да | AL5: нет | AU5: 430 | AV5: 500
B6: iPhone 5C / 5S [BAT] Аккумулятор - Аналог ORIG | C6: 162 011 | D6: 180 | E6: =LEFT(B6,FIND("[",B6) - 2) -> iPhone 5C / 5S | F6: Аккумулятор | G6: iPhone 5s - аккумуляторная батарея (АКБ), ORIG | I6: 370 | L6: 340 | M6: 370 | N6: 0.3 | O6: 500 | P6: =O6 -> 500 | Q6: =P6 -> 500 | R6: https://icomponents.ru/catalog/iphone/iphone_5s/iphone_5s_akkumulyatornaya_batareya_akb_orig/ | S6: 46140.38 | U6: =IF(I6>0, Q6 - I6, "нет з/ч") -> 130 | V6: =IF(L6>0, Q6 - L6, "нет з/ч") -> 160 | X6: 370 | Y6: 340 | AA6: 162 011 | AB6: 162 011 | AD6: 162 011 | AE6: iPhone 5C / 5S [BAT] Аккумулятор - Аналог ORIG | AG6: pcs | AH6: Сервис > Ремонт Apple > Ремонт iPhone > 5C | AI6: 180 | AJ6: дн | AK6: да | AL6: нет | AU6: 370 | AV6: 500
B7: iPhone SE 2016 [BAT] Аккумулятор - Аналог ORIG | C7: 4643 101 | D7: 180 | E7: =LEFT(B7,FIND("[",B7) - 2) -> iPhone SE 2016 | F7: Аккумулятор | G7: iPhone SE - Аккумуляторная батарея (АКБ), ORIG | I7: 530 | L7: 480 | M7: 530 | N7: 0.3 | O7: 700 | P7: =O7 -> 700 | Q7: =P7 -> 700 | R7: https://icomponents.ru/catalog/iphone/iphone_se/iphone_se_akkumulyatornaya_batareya_akb_orig/ | S7: 46140.38 | U7: =IF(I7>0, Q7 - I7, "нет з/ч") -> 170 | V7: =IF(L7>0, Q7 - L7, "нет з/ч") -> 220 | X7: 530 | Y7: 480 | AA7: 4643 101 | AB7: 4643 101 | AD7: 4643 101 | AE7: iPhone SE 2016 [BAT] Аккумулятор - Аналог ORIG | AG7: pcs | AH7: Сервис > Ремонт Apple > Ремонт iPhone > SE2016 | AI7: 180 | AJ7: дн | AK7: да | AL7: нет | AU7: 530 | AV7: 700
B8: iPhone 6 [BAT] Аккумулятор - Аналог ORIG | C8: 228 700 | D8: 180 | E8: =LEFT(B8,FIND("[",B8) - 2) -> iPhone 6 | F8: Аккумулятор | G8: iPhone 6 - аккумуляторная батарея (АКБ), ORIG | I8: 450 | L8: 380 | M8: 450 | N8: 0.3 | O8: 600 | P8: =O8 -> 600 | Q8: =P8 -> 600 | R8: https://icomponents.ru/catalog/iphone/iphone_6/iphone_6_akkumulyatornaya_batareya_akb_orig/ | S8: 46140.38 | U8: =IF(I8>0, Q8 - I8, "нет з/ч") -> 150 | V8: =IF(L8>0, Q8 - L8, "нет з/ч") -> 220 | X8: 450 | Y8: 380 | AA8: 228 700 | AB8: 228 700 | AD8: 228 700 | AE8: iPhone 6 [BAT] Аккумулятор - Аналог ORIG | AG8: pcs | AH8: Сервис > Ремонт Apple > Ремонт iPhone > 6 | AI8: 180 | AJ8: дн | AK8: да | AL8: нет | AU8: 450 | AV8: 600
B9: iPhone 6 Plus [BAT] Аккумулятор - Аналог ORIG | C9: 202 322 | D9: 180 | E9: =LEFT(B9,FIND("[",B9) - 2) -> iPhone 6 Plus | F9: Аккумулятор | G9: iPhone 6+ - Аккумуляторная батарея (АКБ), ORIG | I9: 490 | L9: 480 | M9: 490 | N9: 0.6 | O9: 800 | P9: =O9 -> 800 | Q9: =P9 -> 800 | R9: https://icomponents.ru/catalog/iphone/iphone_6_2/iphone_6_akkumulyatornaya_batareya_akb_orig_2/ | S9: 46140.38 | U9: =IF(I9>0, Q9 - I9, "нет з/ч") -> 310 | V9: =IF(L9>0, Q9 - L9, "нет з/ч") -> 320 | X9: 490 | Y9: 480 | AA9: 202 322 | AB9: 202 322 | AD9: 202 322 | AE9: iPhone 6 Plus [BAT] Аккумулятор - Аналог ORIG | AG9: pcs | AH9: Сервис > Ремонт Apple > Ремонт iPhone > 6 Plus | AI9: 180 | AJ9: дн | AK9: да | AL9: нет | AU9: 490 | AV9: 800
B10: iPhone 6S [BAT] Аккумулятор - Аналог ORIG | C10: 2342 214 | D10: 180 | E10: =LEFT(B10,FIND("[",B10) - 2) -> iPhone 6S | F10: Аккумулятор | G10: iPhone 6s - Аккумуляторная батарея (АКБ), ORIG | I10: 520 | L10: 480 | M10: 520 | N10: 0.5 | O10: 800 | P10: =O10 -> 800 | Q10: =P10 -> 800 | R10: https://icomponents.ru/catalog/iphone/iphone_6s_2/iphone_6s_akkumulyatornaya_batareya_akb_orig/ | S10: 46140.38 | U10: =IF(I10>0, Q10 - I10, "нет з/ч") -> 280 | V10: =IF(L10>0, Q10 - L10, "нет з/ч") -> 320 | X10: 520 | Y10: 480 | AA10: 2342 214 | AB10: 2342 214 | AD10: 2342 214 | AE10: iPhone 6S [BAT] Аккумулятор - Аналог ORIG | AG10: pcs | AH10: Сервис > Ремонт Apple > Ремонт iPhone > 6S | AI10: 180 | AJ10: дн | AK10: да | AL10: нет | AU10: 520 | AV10: 800
B11: iPhone 6S Plus [BAT] Аккумулятор - Аналог ORIG | C11: 531 290 | D11: 180 | E11: =LEFT(B11,FIND("[",B11) - 2) -> iPhone 6S Plus | F11: Аккумулятор | G11: iPhone 6s+ - Аккумуляторная батарея (АКБ), ORIG | I11: 590 | L11: 550 | M11: 590 | N11: 0.7 | O11: 1000 | P11: =O11 -> 1000 | Q11: =P11 -> 1000 | R11: https://icomponents.ru/catalog/iphone/iphone_6s/iphone_6s_akkumulyatornaya_batareya_akb_orig_2/ | S11: 46140.38 | U11: =IF(I11>0, Q11 - I11, "нет з/ч") -> 410 | V11: =IF(L11>0, Q11 - L11, "нет з/ч") -> 450 | X11: 590 | Y11: 550 | AA11: 531 290 | AB11: 531 290 | AD11: 531 290 | AE11: iPhone 6S Plus [BAT] Аккумулятор - Аналог ORIG | AG11: pcs | AH11: Сервис > Ремонт Apple > Ремонт iPhone > 6S Plus | AI11: 180 | AJ11: дн | AK11: да | AL11: нет | AU11: 590 | AV11: 1000
B12: iPhone 7 [BAT] Аккумулятор - Аналог ORIG | C12: 5032 428 | D12: 180 | E12: =LEFT(B12,FIND("[",B12) - 2) -> iPhone 7 | F12: Аккумулятор | G12: iPhone 7 - Аккумуляторная батарея (АКБ), ORIG | I12: 450 | L12: 480 | M12: 480 | N12: 0.5 | O12: 700 | P12: =O12 -> 700 | Q12: =P12 -> 700 | R12: https://icomponents.ru/catalog/iphone/iphone_7_2/iphone_7_akkumulyatornaya_batareya_akb_orig/ | S12: 46140.38 | U12: =IF(I12>0, Q12 - I12, "нет з/ч") -> 250 | V12: =IF(L12>0, Q12 - L12, "нет з/ч") -> 220 | X12: 450 | Y12: 480 | AA12: 5032 428 | AB12: 5032 428 | AD12: 5032 428 | AE12: iPhone 7 [BAT] Аккумулятор - Аналог ORIG | AG12: pcs | AH12: Сервис > Ремонт Apple > Ремонт iPhone > 7 | AI12: 180 | AJ12: дн | AK12: да | AL12: нет | AU12: 480 | AV12: 700
B13: iPhone 7 Plus [BAT] Аккумулятор - Аналог ORIG | C13: 5032 427 | D13: 180 | E13: =LEFT(B13,FIND("[",B13) - 2) -> iPhone 7 Plus | F13: Аккумулятор | G13: iPhone 7+ - Аккумуляторная батарея (АКБ), ORIG | I13: 620 | L13: 570 | M13: 620 | N13: 0.45 | O13: 900 | P13: =O13 -> 900 | Q13: =P13 -> 900 | R13: https://icomponents.ru/catalog/iphone/iphone_7/iphone_7_akkumulyatornaya_batareya_akb_orig_2/ | S13: 46140.38 | U13: =IF(I13>0, Q13 - I13, "нет з/ч") -> 280 | V13: =IF(L13>0, Q13 - L13, "нет з/ч") -> 330 | X13: 620 | Y13: 570 | AA13: 5032 427 | AB13: 5032 427 | AD13: 5032 427 | AE13: iPhone 7 Plus [BAT] Аккумулятор - Аналог ORIG | AG13: pcs | AH13: Сервис > Ремонт Apple > Ремонт iPhone > 7 Plus | AI13: 180 | AJ13: дн | AK13: да | AL13: нет | AU13: 620 | AV13: 900
B14: iPhone 8 [BAT] Аккумулятор - Аналог ORIG | C14: 9340 394 | D14: 180 | E14: =LEFT(B14,FIND("[",B14) - 2) -> iPhone 8 | F14: Аккумулятор | G14: iPhone 8 - Аккумуляторная батарея (АКБ), ORIG | I14: 590 | L14: 550 | M14: 590 | N14: 0.5 | O14: 900 | P14: =O14 -> 900 | Q14: =P14 -> 900 | R14: https://icomponents.ru/catalog/iphone/iphone_8_se2020/iphone_8_akkumulyatornaya_batareya_akb_orig/ | S14: 46140.38 | U14: =IF(I14>0, Q14 - I14, "нет з/ч") -> 310 | V14: =IF(L14>0, Q14 - L14, "нет з/ч") -> 350 | X14: 590 | Y14: 550 | AA14: 9340 394 | AB14: 9340 394 | AD14: 9340 394 | AE14: iPhone 8 [BAT] Аккумулятор - Аналог ORIG | AG14: pcs | AH14: Сервис > Ремонт Apple > Ремонт iPhone > 8 | AI14: 180 | AJ14: дн | AK14: да | AL14: нет | AU14: 590 | AV14: 900
B15: iPhone 8 Plus [BAT] Аккумулятор - Аналог ORIG | C15: 9340 395 | D15: 180 | E15: =LEFT(B15,FIND("[",B15) - 2) -> iPhone 8 Plus | F15: Аккумулятор | G15: iPhone 8+ - Аккумуляторная батарея (АКБ), ORIG | I15: 620 | L15: 610 | M15: 620 | N15: 0.75 | O15: 1100 | P15: =O15 -> 1100 | Q15: =P15 -> 1100 | R15: https://icomponents.ru/catalog/iphone/iphone_8/iphone_8_akkumulyatornaya_batareya_akb_orig_2/ | S15: 46140.38 | U15: =IF(I15>0, Q15 - I15, "нет з/ч") -> 480 | V15: =IF(L15>0, Q15 - L15, "нет з/ч") -> 490 | X15: 620 | Y15: 610 | AA15: 9340 395 | AB15: 9340 395 | AD15: 9340 395 | AE15: iPhone 8 Plus [BAT] Аккумулятор - Аналог ORIG | AG15: pcs | AH15: Сервис > Ремонт Apple > Ремонт iPhone > 8 Plus | AI15: 180 | AJ15: дн | AK15: да | AL15: нет | AU15: 620 | AV15: 1100
B16: iPhone SE 2020 [BAT] Аккумулятор - Аналог ORIG (неизвестная деталь) | C16: 20630 753 | D16: 180 | E16: =LEFT(B16,FIND("[",B16) - 2) -> iPhone SE 2020 | F16: Аккумулятор | G16: iPhone SE 2020 - Аккумуляторная батарея (АКБ), ORIG | I16: 500 | L16: 550 | M16: 550 | N16: 1.4 | O16: 1300 | P16: =O16 -> 1300 | Q16: =P16 -> 1300 | R16: https://icomponents.ru/catalog/iphone/iphone_8_se2020/iphone_se_2020_akkumulyatornaya_batareya_akb_orig/ | S16: 46140.38 | U16: =IF(I16>0, Q16 - I16, "нет з/ч") -> 800 | V16: =IF(L16>0, Q16 - L16, "нет з/ч") -> 750 | X16: 500 | Y16: 550 | AA16: 20630 753 | AB16: 20630 753 | AD16: 20630 753 | AE16: iPhone SE 2020 [BAT] Аккумулятор - Аналог ORIG (неизвестная деталь) | AG16: pcs | AH16: Сервис > Ремонт Apple > Ремонт iPhone > SE 2020 | AI16: 180 | AJ16: дн | AK16: да | AL16: нет | AU16: 550 | AV16: 1300
... B18: iPhone XR [BAT] Аккумулятор - Аналог ORIG (неизвестная деталь) | C18: 14471 928 | D18: 180 | E18: =LEFT(B18,FIND("[",B18) - 2) -> iPhone XR | F18: Аккумулятор | G18: iPhone XR - Аккумуляторная батарея + скотч (АКБ), ORIG | I18: 700 | L18: 710 | M18: 710 | N18: 0.7 | O18: 1200 | P18: =O18 -> 1200 | Q18: =P18 -> 1200 | R18: https://icomponents.ru/catalog/iphone/iphone_xr/iphone_xr_akkumulyatornaya_batareya_skotch_akb_orig/ | S18: 46140.38 | U18: =IF(I18>0, Q18 - I18, "нет з/ч") -> 500 | V18: =IF(L18>0, Q18 - L18, "нет з/ч") -> 490 | X18: 700 | Y18: 710 | AA18: 14471 928 | AB18: 14471 928 | AD18: 14471 928 | AE18: iPhone XR [BAT] Аккумулятор - Аналог ORIG (неизвестная деталь) | AG18: pcs | AH18: Сервис > Ремонт Apple > Ремонт iPhone > XR | AI18: 180 | AJ18: дн | AK18: да | AL18: нет | AU18: 710 | AV18: 1200
B19: iPhone XR [BAT] Аккумулятор - Банка ORIG | C19: 25421 837 | D19: 180 | E19: =LEFT(B19,FIND("[",B19) - 2) -> iPhone XR | F19: Аккумулятор | G19: iPhone XR - Банка АКБ с комплектом наклеек без шлейфа | I19: 390 | M19: 390 | N19: 0.12 | O19: 450 | Q19: =P18 -> 1200 | R19: https://icomponents.ru/catalog/iphone/iphone_xr/iphone_xr_banka_akb_s_komplektom_nakleek_bez_shleyfa/ | S19: 46140.38 | U19: =IF(I19>0, Q19 - I19, "нет з/ч") -> 810 | V19: =IF(L19>0, Q19 - L19, "нет з/ч") -> нет з/ч | X19: 390 | AA19: 25421 837 | AB19: 25421 837 | AD19: 25421 837 | AE19: iPhone XR [BAT] Аккумулятор - Банка ORIG | AG19: pcs | AH19: Сервис > Ремонт Apple > Ремонт iPhone > XR | AI19: 180 | AJ19: дн | AK19: да | AL19: нет | AU19: 390 | AV19: 1200
B20: iPhone X [BAT] Аккумулятор - Аналог ORIG | C20: 9109 216 | D20: 180 | E20: =LEFT(B20,FIND("[",B20) - 2) -> iPhone X | F20: Аккумулятор | G20: iPhone X - Аккумуляторная батарея + скотч (АКБ), ORIG | I20: 750 | L20: 750 | M20: 750 | N20: 0.6 | O20: 1200 | P20: =O20 -> 1200 | Q20: =P20 -> 1200 | R20: https://icomponents.ru/catalog/iphone/iphone_x/iphone_x_akkumulyatornaya_batareya_skotch_akb_orig/ | S20: 46140.38 | U20: =IF(I20>0, Q20 - I20, "нет з/ч") -> 450 | V20: =IF(L20>0, Q20 - L20, "нет з/ч") -> 450 | X20: 750 | Y20: 750 | AA20: 9109 216 | AB20: 9109 216 | AD20: 9109 216 | AE20: iPhone X [BAT] Аккумулятор - Аналог ORIG | AG20: pcs | AH20: Сервис > Ремонт Apple > Ремонт iPhone > X | AI20: 180 | AJ20: дн | AK20: да | AL20: нет | AU20: 750 | AV20: 1200
B21: iPhone XS [BAT] Аккумулятор - Аналог ORIG (неизвестная деталь) | C21: 14197 590 | D21: 180 | E21: =LEFT(B21,FIND("[",B21) - 2) -> iPhone XS | F21: Аккумулятор | G21: iPhone XS - Аккумуляторная батарея + скотч (АКБ), ORIG | I21: 800 | L21: 750 | M21: 800 | N21: 0.5 | O21: 1200 | P21: =O21 -> 1200 | Q21: =P21 -> 1200 | R21: https://icomponents.ru/catalog/iphone/iphone_xs/iphone_xs_akkumulyatornaya_batareya_skotch_akb_orig/ | S21: 46140.38 | U21: =IF(I21>0, Q21 - I21, "нет з/ч") -> 400 | V21: =IF(L21>0, Q21 - L21, "нет з/ч") -> 450 | X21: 800 | Y21: 750 | AA21: 14197 590 | AB21: 14197 590 | AD21: 14197 590 | AE21: iPhone XS [BAT] Аккумулятор - Аналог ORIG (неизвестная деталь) | AG21: pcs | AH21: Сервис > Ремонт Apple > Ремонт iPhone > XS | AI21: 180 | AJ21: дн | AK21: да | AL21: нет | AU21: 800 | AV21: 1200
B22: iPhone XS [BAT] Аккумулятор - Банка ORIG | C22: 25245 934 | D22: 180 | E22: =LEFT(B22,FIND("[",B22) - 2) -> iPhone XS | F22: Аккумулятор | G22: iPhone XS - Банка АКБ с комплектом наклеек без шлейфа | I22: 530 | M22: 530 | N22: 0.12 | O22: 600 | Q22: =P21 -> 1200 | R22: https://icomponents.ru/catalog/iphone/iphone_xs/iphone_xs_banka_akb_s_komplektom_nakleek_bez_shleyfa/ | S22: 46140.38 | U22: =IF(I22>0, Q22 - I22, "нет з/ч") -> 670 | V22: =IF(L22>0, Q22 - L22, "нет з/ч") -> нет з/ч | X22: 530 | AA22: 25245 934 | AB22: 25245 934 | AD22: 25245 934 | AE22: iPhone XS [BAT] Аккумулятор - Банка ORIG | AG22: pcs | AH22: Сервис > Ремонт Apple > Ремонт iPhone > XS | AI22: 180 | AJ22: дн | AK22: да | AL22: нет | AU22: 530 | AV22: 1200
B23: iPhone XS Max [BAT] Аккумулятор - Аналог ORIG (неизвестная деталь) | C23: 14197 591 | D23: 180 | E23: =LEFT(B23,FIND("[",B23) - 2) -> iPhone XS Max | F23: Аккумулятор | G23: iPhone XS MAX - Аккумуляторная батарея + скотч (АКБ), ORIG | I23: 850 | L23: 750 | M23: 850 | N23: 1 | O23: 1700 | P23: =O23 -> 1700 | Q23: =P23 -> 1700 | R23: https://icomponents.ru/catalog/iphone/iphone_xs_max/iphone_xs_max_akkumulyatornaya_batareya_skotch_akb_orig/ | S23: 46140.38 | U23: =IF(I23>0, Q23 - I23, "нет з/ч") -> 850 | V23: =IF(L23>0, Q23 - L23, "нет з/ч") -> 950 | X23: 850 | Y23: 750 | AA23: 14197 591 | AB23: 14197 591 | AD23: 14197 591 | AE23: iPhone XS Max [BAT] Аккумулятор - Аналог ORIG (неизвестная деталь) | AG23: pcs | AH23: Сервис > Ремонт Apple > Ремонт iPhone > XS Max | AI23: 180 | AJ23: дн | AK23: да | AL23: нет | AU23: 850 | AV23: 1700
B24: iPhone XS Max [BAT] Аккумулятор - Банка ORIG | C24: 25245 979 | D24: 180 | E24: =LEFT(B24,FIND("[",B24) - 2) -> iPhone XS Max | F24: Аккумулятор | G24: iPhone XS Max - Банка АКБ с комплектом наклеек без шлейфа | I24: 550 | M24: 550 | N24: 0.12 | O24: 600 | Q24: =P23 -> 1700 | R24: https://icomponents.ru/catalog/iphone/iphone_xs_max/iphone_xs_max_banka_akb_s_komplektom_nakleek_bez_shleyfa/ | S24: 46140.38 | U24: =IF(I24>0, Q24 - I24, "нет з/ч") -> 1150 | V24: =IF(L24>0, Q24 - L24, "нет з/ч") -> нет з/ч | X24: 550 | AA24: 25245 979 | AB24: 25245 979 | AD24: 25245 979 | AE24: iPhone XS Max [BAT] Аккумулятор - Банка ORIG | AG24: pcs | AH24: Сервис > Ремонт Apple > Ремонт iPhone > XS Max | AI24: 180 | AJ24: дн | AK24: да | AL24: нет | AU24: 550 | AV24: 1700
B25: iPhone 11 [BAT] Аккумулятор - Аналог ORIG (неизвестная деталь) | C25: 24010 460 | D25: 180 | E25: =LEFT(B25,FIND("[",B25) - 2) -> iPhone 11 | F25: Аккумулятор | G25: iPhone 11 - Аккумуляторная батарея + скотч (АКБ), ORIG | I25: 700 | L25: 790 | M25: 790 | N25: 0.12 | O25: 900 | P25: =O25 -> 900 | Q25: =P25 -> 900 | R25: https://icomponents.ru/catalog/iphone/iphone_11/iphone_11_akkumulyatornaya_batareya_skotch_akb_orig/ | S25: 46140.381 | U25: =IF(I25>0, Q25 - I25, "нет з/ч") -> 200 | V25: =IF(L25>0, Q25 - L25, "нет з/ч") -> 110 | X25: 700 | Y25: 790 | AA25: 24010 460 | AB25: 24010 460 | AD25: 24010 460 | AE25: iPhone 11 [BAT] Аккумулятор - Аналог ORIG (неизвестная деталь) | AG25: pcs | AH25: Сервис > Ремонт Apple > Ремонт iPhone > 11 | AI25: 180 | AJ25: дн | AK25: да | AL25: нет | AU25: 790 | AV25: 900
B26: iPhone 11 [BAT] Аккумулятор - Банка ORIG | C26: 37706 712 | D26: 180 | E26: =LEFT(B26,FIND("[",B26) - 2) -> iPhone 11 | F26: Аккумулятор | G26: iPhone 11 - Банка АКБ с комплектом наклеек без шлейфа | I26: 399 | M26: 399 | N26: 0.12 | O26: 450 | Q26: =P25 -> 900 | R26: https://icomponents.ru/catalog/iphone/iphone_11/iphone_11_banka_akb_s_komplektom_nakleek_bez_shleyfa/ | S26: 46140.381 | U26: =IF(I26>0, Q26 - I26, "нет з/ч") -> 501 | V26: =IF(L26>0, Q26 - L26, "нет з/ч") -> нет з/ч | X26: 399 | AA26: 37706 712 | AB26: 37706 712 | AD26: 37706 712 | AE26: iPhone 11 [BAT] Аккумулятор - Банка ORIG | AG26: pcs | AH26: Сервис > Ремонт Apple > Ремонт iPhone > 11 | AI26: 180 | AJ26: дн | AK26: да | AL26: нет | AU26: 399 | AV26: 900
B27: iPhone 11 Pro [BAT] Аккумулятор - Аналог ORIG (неизвестная деталь) | C27: 22608 232 | D27: 180 | E27: =LEFT(B27,FIND("[",B27) - 2) -> iPhone 11 Pro | F27: Аккумулятор | G27: iPhone 11 Pro - Аккумуляторная батарея + скотч (АКБ), ORIG | I27: 950 | L27: 950 | M27: 950 | N27: 0.48 | O27: 1400 | P27: =O27 -> 1400 | Q27: =P27 -> 1400 | R27: https://icomponents.ru/catalog/iphone/iphone_11_pro/iphone_11_pro_akkumulyatornaya_batareya_skotch_akb_orig/ | S27: 46140.381 | U27: =IF(I27>0, Q27 - I27, "нет з/ч") -> 450 | V27: =IF(L27>0, Q27 - L27, "нет з/ч") -> 450 | X27: 950 | Y27: 950 | AA27: 22608 232 | AB27: 22608 232 | AD27: 22608 232 | AE27: iPhone 11 Pro [BAT] Аккумулятор - Аналог ORIG (неизвестная деталь) | AG27: pcs | AH27: Сервис > Ремонт Apple > Ремонт iPhone > 11 Pro | AI27: 180 | AJ27: дн | AK27: да | AL27: нет | AU27: 950 | AV27: 1400
B28: iPhone 11 Pro [BAT] Аккумулятор - Банка ORIG | C28: 25246 105 | D28: 180 | E28: =LEFT(B28,FIND("[",B28) - 2) -> iPhone 11 Pro | F28: Аккумулятор | G28: iPhone 11 Pro - Банка АКБ с комплектом наклеек без шлейфа | I28: 650 | M28: 650 | N28: 0.12 | O28: 750 | Q28: =P27 -> 1400 | R28: https://icomponents.ru/catalog/iphone/iphone_11_pro/iphone_11_pro_banka_akb_s_komplektom_nakleek_bez_shleyfa/ | S28: 46140.381 | U28: =IF(I28>0, Q28 - I28, "нет з/ч") -> 750 | V28: =IF(L28>0, Q28 - L28, "нет з/ч") -> нет з/ч | X28: 650 | AA28: 25246 105 | AB28: 25246 105 | AD28: 25246 105 | AE28: iPhone 11 Pro [BAT] Аккумулятор - Банка ORIG | AG28: pcs | AH28: Сервис > Ремонт Apple > Ремонт iPhone > 11 Pro | AI28: 180 | AJ28: дн | AK28: да | AL28: нет | AU28: 650 | AV28: 1400
